Workbook

Sheet Calculator
B1: EIDA FRAMEWORK · CLOSED-FORM MEDIAN-CAPACITY SCREENING CALCULATOR
B2: Gravity-designed, non-seismically detailed RC bare frames · Shafiq et al., Structures 94 (2026) 113186 · doi:10.1016/j.istruc.2026.113186
B3: Yellow cells are inputs. Everything else is calculated. Coefficients live on the Equations sheet; Batch screens many frames; Verification reproduces Table A.17.
B5: STEP 00 · PROJECT
B6: Project name | C6: Example frame | G6: Date | H6: =TODAY() -> 46305
B7: Location | G7: Input mode | H7: Drawings
B8: Engineer / user | G8: Drawings: T̄, SR, λeff are computed from the Step 01 inputs. Macro-parameters: the values typed in H22:H24 are used instead (e.g. a modal period).
B9: Reference
B11: STEP 01 · INPUTS FROM DRAWINGS | G11: STEP 02 · MACRO-PARAMETERS & APPLICABILITY
B12: Parameter | C12: Symbol | D12: Value | E12: Unit | G12: Parameter | H12: Value used | I12: Applicability | J12: Status
B13: Storeys (total, incl. rooftop addition) | C13: N | D13: 3 | E13: – | G13: From drawings: T̄ = T√(g/H) | H13: =D34*SQRT(9.81/D14) -> 0.4177301 | I13: Table 3 definition
B14: Total height | C14: H | D14: 10 | E14: m | G14: From drawings: SR = (bc·hc³/bb·hb³)(B/H)³ | H14: =(D17*D18^3/(D19*D20^3))*(D33/D14)^3 -> 1.9418074 | I14: Table 3 definition
B15: Plan width | C15: W | D15: 12 | E15: m | G15: From drawings: λeff = (H/B)(1−Iv) | H15: =(D14/D33)*(1-D37) -> 0.83333333 | I15: Table 3 definition
B16: Plan span | C16: S | D16: 12 | E16: m
B17: Dominant column width | C17: bc | D17: 0.4 | E17: m | G17: Normalised period, T̄ | H17: =IF($H$7="Macro-parameters",H22,H13) -> 0.4177301 | I17: 0.174 – 1.486 (Table 11) | J17: =IF(AND(H17>=0.174,H17<=1.486),"In range","Extrapolation") -> In range
B18: Dominant column depth | C18: hc | D18: 0.4 | E18: m | G18: Stiffness ratio, SR | H18: =IF($H$7="Macro-parameters",H23,H14) -> 1.9418074 | I18: 0.00 – 13.05 (Table 11, 5–95 pct.) | J18: =IF(AND(H18>=0,H18<=13.05),"In range","Extrapolation") -> In range
B19: Dominant beam width | C19: bb | D19: 0.25 | E19: m | G19: Effective slenderness, λeff | H19: =IF($H$7="Macro-parameters",H24,H15) -> 0.83333333 | I19: 0.25 – 4.55 (training 5–95 pct.) | J19: =IF(AND(H19>=0.25,H19<=4.55),"In range","Extrapolation") -> In range
B20: Dominant beam depth | C20: hb | D20: 0.45 | E20: m
B21: Typical-floor bays X | C21: nx | D21: 3 | E21: – | G21: Macro-parameter inputs (used only when Input mode = Macro-parameters)
B22: Typical-floor bays Y | C22: ny | D22: 3 | E22: – | G22: T̄ (direct) | H22: 0.6
B23: Top-storey bays X | C23: ntx | D23: 3 | E23: – | G23: SR (direct) | H23: 2
B24: Top-storey bays Y | C24: nty | D24: 3 | E24: – | G24: λeff (direct) | H24: 1.2
B25: Concrete strength | C25: f'c | D25: 25 | E25: MPa
B26: Steel yield strength | C26: fy | D26: 420 | E26: MPa | G26: Table 11 checks | H26: Status
B27: Foundation condition | C27: – | D27: Other | G27: Storeys 1–10 | H27: =IF(AND(D13>=1,D13<=10),"OK","Outside 1–10 storeys") -> OK
B28: Structural system | C28: – | D28: Bare RC frame (gravity-designed) | G28: Bay aspect ratio 1/3–3 | H28: =IF(AND(D38>=1/3-0.000001,D38<=3.000001),"OK","Outside 1/3–3") -> OK
B29: Site PGA | C29: ag | D29: 0.25 | E29: g | G29: f'c 20–35 MPa | H29: =IF(AND(D25>=20,D25<=35),"OK","Outside 20–35 MPa") -> OK
B30: Lognormal dispersion | C30: β | D30: 0.4 | E30: – | G30: fy 280–550 MPa | H30: =IF(AND(D26>=280,D26<=550),"OK","Outside 280–550 MPa") -> OK
G31: Foundation condition | H31: =IF(D27="Other","Outside: fixed or clay SSI only","OK") -> Outside: fixed or clay SSI only
B32: DERIVED GEOMETRY | G32: Structural system | H32: =IF(LEFT(D28,4)="Bare","OK","Outside typology: do not apply") -> OK
B33: Shortest base width, B = min(W,S) | C33: B | D33: =MIN(D15,D16) -> 12 | E33: m | G33: Top storey within grid | H33: =IF(AND(D23<=D21,D24<=D22),"OK","Top storey exceeds grid") -> OK
B34: Estimated period, T = 0.075H^0.75 | C34: T | D34: =0.075*D14^0.75 -> 0.42175599 | E34: s | G34: Applicability summary | H34: =IF(AND(COUNTIF(H27:H33,"OK")=7,COUNTIF(J17:J19,"In range")=3),"Within the applicability matrix",IF(COUNTIF(H27:H33,"OK")<7,"Outside the applicability matrix: see checks","Macro-parameter extrapolation: interpret with caution")) -> Outside the applicability matrix: see checks
B35: Top-storey coverage | C35: cov | D35: =MIN(1,(D23*D24)/(D21*D22)) -> 1 | E35: – | G35: In Drawings mode the Table 11 checks apply to the drawing inputs. In Macro-parameters mode only the T̄, SR, λeff ranges are meaningful.
B36: Rooftop addition ratio ρtop | C36: ρtop | D36: =IF(D35>=0.999,0,D35) -> 0 | E36: –
B37: Irregularity index Iv = ρtop/(N+ρtop) | C37: Iv | D37: =D36/(D13+D36) -> 0 | E37: –
B38: Bay aspect ratio (W/nx)/(S/ny) | C38: AR | D38: =(D15/D21)/(D16/D22) -> 1 | E38: – | G38: STEP 03 · MEDIAN PGA CAPACITY μ̂ (g)
G39: Damage state | H39: Raw equation | I39: μ̂ after sign check | J39: Use (paper)
B40: POLYNOMIAL TERMS (values used in Step 02) | G40: DS1 · Slight | H40: =SUMPRODUCT(Equations!$C$6:$C$15,$C$41:$C$50) -> 0.34444603 | I40: =IF(H40<=0,0.01,H40) -> 0.34444603 | J40: Transferable estimator
B41: term: 1 | C41: =1 -> 1 | G41: DS2 · Moderate | H41: =SUMPRODUCT(Equations!$D$6:$D$15,$C$41:$C$50) -> 0.72239481 | I41: =IF(H41<=0,0.01,H41) -> 0.72239481 | J41: Internal only
B42: term: T̄ | C42: =H17 -> 0.4177301 | G42: DS3 · Extensive | H42: =SUMPRODUCT(Equations!$E$6:$E$15,$C$41:$C$50) -> 1.693023 | I42: =IF(H42<=0,0.01,H42) -> 1.693023 | J42: Diagnostic only
...

Sheet Equations
B1: RECOMMENDED EQUATIONS · COEFFICIENT TABLE
B2: μ̂(g) = Σ coefficient × term. Source: Shafiq et al., Structures 94 (2026) 113186, Section 3.6 (main-text equations). Zero = inactive term. Every calculator, batch and verification formula reads its coefficients from this table.
B4: COEFFICIENTS (main text, Section 3.6) | H4: BOOTSTRAP SELECTION FREQUENCY % (Table A.18)
B5: Term | C5: DS1 | D5: DS2 | E5: DS3 | F5: DS4 | H5: DS1 | I5: DS2 | J5: DS3 | K5: DS4
B6: 1 | C6: 0.4522 | D6: 1.1429 | E6: 1.2876 | F6: 2.4999 | H6: 100 | I6: 100 | J6: 100 | K6: 100
B7: T̄ | C7: -0.7877 | D7: -1.9974 | E7: 0 | F7: 0 | H7: 100 | I7: 99 | J7: 77 | K7: 14
B8: SR | C8: 0.1618 | D8: 0.1648 | E8: 0.2194 | F8: 0 | H8: 100 | I8: 88 | J8: 93 | K8: 27.5
B9: λeff | C9: -0.0578 | D9: 0 | E9: 0 | F9: 0 | H9: 96 | I9: 40 | J9: 73.5 | K9: 0.5
B10: T̄² | C10: 0.4086 | D10: 0.9955 | E10: -0.4977 | F10: -1.134 | H10: 98.5 | I10: 98 | J10: 98 | K10: 69.5
B11: T̄·SR | C11: -0.0952 | D11: -0.0845 | E11: 0.1221 | F11: 0.3279 | H11: 99 | I11: 72.5 | J11: 94.5 | K11: 64.5
B12: T̄·λeff | C12: 0.026 | D12: 0 | E12: 0 | F12: 0 | H12: 84.5 | I12: 34.5 | J12: 75 | K12: 3.5
B13: SR² | C13: -0.003 | D13: -0.003 | E13: -0.0073 | F13: 0 | H13: 98.5 | I13: 71 | J13: 89 | K13: 27
B14: SR·λeff | C14: -0.0246 | D14: 0 | E14: 0 | F14: 0 | H14: 92.5 | I14: 48.5 | J14: 89.5 | K14: 11.5
B15: λeff² | C15: 0.0047 | D15: 0 | E15: -0.0076 | F15: 0 | H15: 86.5 | I15: 9 | J15: 79 | K15: 1.5
B17: SELECTION AND RELIABILITY (Tables 9, 10, 12; Section 3.7)
B18: DS | C18: Method | D18: Active terms | E18: R² repeated-CV | F18: R² internal test | G18: Repeated split (mean ± SD) | H18: R²ext config | I18: R²ext study | J18: LOSO range | K18: Use (paper)
B19: DS1 | C19: Elastic Net | D19: 10 | E19: 0.812 | F19: 0.94 | G19: 0.877 ± 0.132 | H19: 0.408 | I19: 0.31 | J19: 0.352 to 0.470 | K19: Transferable first-order estimator
B20: DS2 | C20: Stepwise (BIC) | D20: 6 | E20: 0.681 | F20: 0.809 | G20: 0.568 ± 0.337 | H20: 0.091 | I20: -0.299 | J20: 0.017 to 0.130 | K20: Internally reliable; no study-level transferability
B21: DS3 | C21: Elastic Net | D21: 6 | E21: 0.307 | F21: 0.474 | G21: 0.277 ± 0.231 | H21: -1.024 | I21: -5.348 | J21: −2.623 to −0.783 | K21: Diagnostic only
B22: DS4 | C22: Stepwise (BIC) | D22: 3 | E22: 0.154 | F22: 0.251 | G22: 0.042 ± 0.413 | H22: -0.795 | I22: -5.554 | J22: −3.471 to −0.480 | K22: Diagnostic only
B24: Notes. Equations are degree-2 polynomials (poly2-std) selected by Score = R²CV,repeated − 0.01·N_terms, frozen before any external data were used. R²ext uses 63 configurations from 10 studies; "study" collapses each study to one observation (the more conservative reading). LOSO = leave-one-study-out range of the configuration-level R². Mandatory post-processing (Section 5): clip or flag negative μ̂, and check μ̂DS1 ≤ μ̂DS2 ≤ μ̂DS3 ≤ μ̂DS4. Only DS1 can go negative inside the applicability box, where high SR coincides with high λeff (SR–λeff correlation in training r = −0.48).

Sheet Fragility Data
A1: PGA (g) | B1: DS1 Slight | C1: DS2 Moderate | D1: DS3 (diagnostic) | E1: DS4 (diagnostic) | G1: Site PGA | H1: P | J1: P(DS≥ds|PGA) = Φ[ln(PGA/μ̂)/β], μ̂ after the sign check, β from Calculator!D30. DS3–DS4 are diagnostic only.
A2: 0.01 | B2: =NORMSDIST(LN(A2/Calculator!$I$40)/Calculator!$D$30) -> 4.4399103e-19 | C2: =NORMSDIST(LN(A2/Calculator!$I$41)/Calculator!$D$30) -> 5.090733e-27 | D2: =NORMSDIST(LN(A2/Calculator!$I$42)/Calculator!$D$30) -> 5.6249354e-38 | E2: =NORMSDIST(LN(A2/Calculator!$I$43)/Calculator!$D$30) -> 4.764473e-44 | G2: =Calculator!$D$29 -> 0.25 | H2: 0
A3: 0.03 | B3: =NORMSDIST(LN(A3/Calculator!$I$40)/Calculator!$D$30) -> 5.2423848e-10 | C3: =NORMSDIST(LN(A3/Calculator!$I$41)/Calculator!$D$30) -> 9.0704179e-16 | D3: =NORMSDIST(LN(A3/Calculator!$I$42)/Calculator!$D$30) -> 3.2950479e-24 | E3: =NORMSDIST(LN(A3/Calculator!$I$43)/Calculator!$D$30) -> 4.7825438e-29 | G3: =Calculator!$D$29 -> 0.25 | H3: 1
A4: 0.05 | B4: =NORMSDIST(LN(A4/Calculator!$I$40)/Calculator!$D$30) -> 7.0076827e-07 | C4: =NORMSDIST(LN(A4/Calculator!$I$41)/Calculator!$D$30) -> 1.2246486e-11 | D4: =NORMSDIST(LN(A4/Calculator!$I$42)/Calculator!$D$30) -> 6.506568e-19 | E4: =NORMSDIST(LN(A4/Calculator!$I$43)/Calculator!$D$30) -> 3.5259475e-23
A5: 0.07 | B5: =NORMSDIST(LN(A5/Calculator!$I$40)/Calculator!$D$30) -> 3.3938769e-05 | C5: =NORMSDIST(LN(A5/Calculator!$I$41)/Calculator!$D$30) -> 2.6864418e-09 | D5: =NORMSDIST(LN(A5/Calculator!$I$42)/Calculator!$D$30) -> 8.298732e-16 | E5: =NORMSDIST(LN(A5/Calculator!$I$43)/Calculator!$D$30) -> 1.0688965e-19
A6: 0.09 | B6: =NORMSDIST(LN(A6/Calculator!$I$40)/Calculator!$D$30) -> 0.00039636705 | C6: =NORMSDIST(LN(A6/Calculator!$I$41)/Calculator!$D$30) -> 9.6007968e-08 | D6: =NORMSDIST(LN(A6/Calculator!$I$42)/Calculator!$D$30) -> 1.0991018e-13 | E6: =NORMSDIST(LN(A6/Calculator!$I$43)/Calculator!$D$30) -> 2.6991061e-17
A7: 0.11 | B7: =NORMSDIST(LN(A7/Calculator!$I$40)/Calculator!$D$30) -> 0.0021610561 | C7: =NORMSDIST(LN(A7/Calculator!$I$41)/Calculator!$D$30) -> 1.2679079e-06 | D7: =NORMSDIST(LN(A7/Calculator!$I$42)/Calculator!$D$30) -> 4.1152518e-12 | E7: =NORMSDIST(LN(A7/Calculator!$I$43)/Calculator!$D$30) -> 1.6901251e-15
A8: 0.13 | B8: =NORMSDIST(LN(A8/Calculator!$I$40)/Calculator!$D$30) -> 0.0074251902 | C8: =NORMSDIST(LN(A8/Calculator!$I$41)/Calculator!$D$30) -> 9.0309646e-06 | D8: =NORMSDIST(LN(A8/Calculator!$I$42)/Calculator!$D$30) -> 6.9565426e-11 | E8: =NORMSDIST(LN(A8/Calculator!$I$43)/Calculator!$D$30) -> 4.3801031e-14
A9: 0.15 | B9: =NORMSDIST(LN(A9/Calculator!$I$40)/Calculator!$D$30) -> 0.018842926 | C9: =NORMSDIST(LN(A9/Calculator!$I$41)/Calculator!$D$30) -> 4.2500968e-05 | D9: =NORMSDIST(LN(A9/Calculator!$I$42)/Calculator!$D$30) -> 6.844725e-10 | E9: =NORMSDIST(LN(A9/Calculator!$I$43)/Calculator!$D$30) -> 6.2101975e-13
A10: 0.17 | B10: =NORMSDIST(LN(A10/Calculator!$I$40)/Calculator!$D$30) -> 0.038752695 | C10: =NORMSDIST(LN(A10/Calculator!$I$41)/Calculator!$D$30) -> 0.00014905695 | D10: =NORMSDIST(LN(A10/Calculator!$I$42)/Calculator!$D$30) -> 4.5640715e-09 | E10: =NORMSDIST(LN(A10/Calculator!$I$43)/Calculator!$D$30) -> 5.6965254e-12
A11: 0.19 | B11: =NORMSDIST(LN(A11/Calculator!$I$40)/Calculator!$D$30) -> 0.068469994 | C11: =NORMSDIST(LN(A11/Calculator!$I$41)/Calculator!$D$30) -> 0.00042060054 | D11: =NORMSDIST(LN(A11/Calculator!$I$42)/Calculator!$D$30) -> 2.2742053e-08 | E11: =NORMSDIST(LN(A11/Calculator!$I$43)/Calculator!$D$30) -> 3.7665077e-11
A12: 0.21 | B12: =NORMSDIST(LN(A12/Calculator!$I$40)/Calculator!$D$30) -> 0.10802967 | C12: =NORMSDIST(LN(A12/Calculator!$I$41)/Calculator!$D$30) -> 0.0010053045 | D12: =NORMSDIST(LN(A12/Calculator!$I$42)/Calculator!$D$30) -> 9.0477372e-08 | E12: =NORMSDIST(LN(A12/Calculator!$I$43)/Calculator!$D$30) -> 1.931895e-10
A13: 0.23 | B13: =NORMSDIST(LN(A13/Calculator!$I$40)/Calculator!$D$30) -> 0.15633264 | C13: =NORMSDIST(LN(A13/Calculator!$I$41)/Calculator!$D$30) -> 0.0021099953 | D13: =NORMSDIST(LN(A13/Calculator!$I$42)/Calculator!$D$30) -> 3.0114855e-07 | E13: =NORMSDIST(LN(A13/Calculator!$I$43)/Calculator!$D$30) -> 8.0969468e-10
A14: 0.25 | B14: =NORMSDIST(LN(A14/Calculator!$I$40)/Calculator!$D$30) -> 0.21151047 | C14: =NORMSDIST(LN(A14/Calculator!$I$41)/Calculator!$D$30) -> 0.0039916266 | D14: =NORMSDIST(LN(A14/Calculator!$I$42)/Calculator!$D$30) -> 8.6769001e-07 | E14: =NORMSDIST(LN(A14/Calculator!$I$43)/Calculator!$D$30) -> 2.8805317e-09
A15: 0.27 | B15: =NORMSDIST(LN(A15/Calculator!$I$40)/Calculator!$D$30) -> 0.27133227 | C15: =NORMSDIST(LN(A15/Calculator!$I$41)/Calculator!$D$30) -> 0.0069396021 | D15: =NORMSDIST(LN(A15/Calculator!$I$42)/Calculator!$D$30) -> 2.2202417e-06 | E15: =NORMSDIST(LN(A15/Calculator!$I$43)/Calculator!$D$30) -> 8.9507424e-09
... A201: 3.99 | B201: =NORMSDIST(LN(A201/Calculator!$I$40)/Calculator!$D$30) -> 1 | C201: =NORMSDIST(LN(A201/Calculator!$I$41)/Calculator!$D$30) -> 0.99999033 | D201: =NORMSDIST(LN(A201/Calculator!$I$42)/Calculator!$D$30) -> 0.98395103 | E201: =NORMSDIST(LN(A201/Calculator!$I$43)/Calculator!$D$30) -> 0.86469615

Sheet Batch
A1: BATCH SCREENING · one frame per row · yellow = inputs · same equations and checks as the Calculator
A2: Rows with a blank N are ignored. T = 0.075H^0.75; ρtop = 0 when the top storey covers the full grid. Range check uses T̄ 0.174–1.486, SR 0–13.05, λeff 0.25–4.55 and N 1–10. Decision is this tool's convention, not part of the paper.
A4: Frame ID | B4: N | C4: H (m) | D4: W (m) | E4: S (m) | F4: bc (m) | G4: hc (m) | H4: bb (m) | I4: hb (m) | J4: nx | K4: ny | L4: Top nx | M4: Top ny | N4: ag (g) | O4: B (m) | P4: T (s) | Q4: ρtop | R4: Iv | S4: T̄ | T4: SR | U4: λeff | V4: μ̂DS1 raw | W4: μ̂DS2 raw | X4: μ̂DS3 raw | Y4: μ̂DS4 raw | Z4: Range check | AA4: Sign check | AB4: Order check | AC4: Decision
A5: Example A | B5: 3 | C5: 10 | D5: 12 | E5: 12 | F5: 0.4 | G5: 0.4 | H5: 0.25 | I5: 0.45 | J5: 3 | K5: 3 | L5: 3 | M5: 3 | N5: 0.25 | O5: =IF($B5="","",MIN(D5,E5)) -> 12 | P5: =IF($B5="","",0.075*C5^0.75) -> 0.42175599 | Q5: =IF($B5="","",IF(MIN(1,(L5*M5)/(J5*K5))>=0.999,0,MIN(1,(L5*M5)/(J5*K5)))) -> 0 | R5: =IF($B5="","",Q5/(B5+Q5)) -> 0 | S5: =IF($B5="","",P5*SQRT(9.81/C5)) -> 0.4177301 | T5: =IF($B5="","",(F5*G5^3/(H5*I5^3))*(O5/C5)^3) -> 1.9418074 | U5: =IF($B5="","",(C5/O5)*(1-R5)) -> 0.83333333 | V5: =IF($B5="","",Equations!$C$6+Equations!$C$7*S5+Equations!$C$8*T5+Equations!$C$9*U5+Equations!$C$10*S5^2+Equations!$C$11*S5*T5+Equations!$C$12*S5*U5+Equations!$C$13*T5^2+Equations!$C$14*T5*U5+Equations!$C$15*U5^2) -> 0.34444603 | W5: =IF($B5="","",Equations!$D$6+Equations!$D$7*S5+Equations!$D$8*T5+Equations!$D$10*S5^2+Equations!$D$11*S5*T5+Equations!$D$13*T5^2) -> 0.72239481 | X5: =IF($B5="","",Equations!$E$6+Equations!$E$8*T5+Equations!$E$10*S5^2+Equations!$E$11*S5*T5+Equations!$E$13*T5^2+Equations!$E$15*U5^2) -> 1.693023 | Y5: =IF($B5="","",Equations!$F$6+Equations!$F$10*S5^2+Equations!$F$11*S5*T5) -> 2.5679953 | Z5: =IF($B5="","",IF(AND(S5>=0.174,S5<=1.486,T5>=0,T5<=13.05,U5>=0.25,U5<=4.55,B5>=1,B5<=10),"In range","Extrapolation")) -> In range | AA5: =IF($B5="","",IF(MIN(V5:Y5)<=0,"Fail (<0)","Pass")) -> Pass | AB5: =IF($B5="","",IF(AND(V5<=W5,W5<=X5,X5<=Y5),"Pass","Fail")) -> Pass | AC5: =IF($B5="","",IF(OR(V5<=0,W5<=0,V5>W5),"Cannot classify",IF(N5<V5,"Low",IF(N5<W5,"Moderate","High")))) -> Low
A6: Example B | B6: 5 | C6: 16 | D6: 18 | E6: 18 | F6: 0.5 | G6: 0.5 | H6: 0.3 | I6: 0.65 | J6: 3 | K6: 3 | L6: 2 | M6: 3 | N6: 0.3 | O6: =IF($B6="","",MIN(D6,E6)) -> 18 | P6: =IF($B6="","",0.075*C6^0.75) -> 0.6 | Q6: =IF($B6="","",IF(MIN(1,(L6*M6)/(J6*K6))>=0.999,0,MIN(1,(L6*M6)/(J6*K6)))) -> 0.66666667 | R6: =IF($B6="","",Q6/(B6+Q6)) -> 0.11764706 | S6: =IF($B6="","",P6*SQRT(9.81/C6)) -> 0.46981379 | T6: =IF($B6="","",(F6*G6^3/(H6*I6^3))*(O6/C6)^3) -> 1.0801306 | U6: =IF($B6="","",(C6/O6)*(1-R6)) -> 0.78431373 | V6: =IF($B6="","",Equations!$C$6+Equations!$C$7*S6+Equations!$C$8*T6+Equations!$C$9*U6+Equations!$C$10*S6^2+Equations!$C$11*S6*T6+Equations!$C$12*S6*U6+Equations!$C$13*T6^2+Equations!$C$14*T6*U6+Equations!$C$15*U6^2) -> 0.24156899 | W6: =IF($B6="","",Equations!$D$6+Equations!$D$7*S6+Equations!$D$8*T6+Equations!$D$10*S6^2+Equations!$D$11*S6*T6+Equations!$D$13*T6^2) -> 0.55585075 | X6: =IF($B6="","",Equations!$E$6+Equations!$E$8*T6+Equations!$E$10*S6^2+Equations!$E$11*S6*T6+Equations!$E$13*T6^2+Equations!$E$15*U6^2) -> 1.4634948 | Y6: =IF($B6="","",Equations!$F$6+Equations!$F$10*S6^2+Equations!$F$11*S6*T6) -> 2.4159941 | Z6: =IF($B6="","",IF(AND(S6>=0.174,S6<=1.486,T6>=0,T6<=13.05,U6>=0.25,U6<=4.55,B6>=1,B6<=10),"In range","Extrapolation")) -> In range | AA6: =IF($B6="","",IF(MIN(V6:Y6)<=0,"Fail (<0)","Pass")) -> Pass | AB6: =IF($B6="","",IF(AND(V6<=W6,W6<=X6,X6<=Y6),"Pass","Fail")) -> Pass | AC6: =IF($B6="","",IF(OR(V6<=0,W6<=0,V6>W6),"Cannot classify",IF(N6<V6,"Low",IF(N6<W6,"Moderate","High")))) -> Moderate
A7: Example C | B7: 8 | C7: 25 | D7: 15 | E7: 18 | F7: 0.6 | G7: 0.6 | H7: 0.35 | I7: 0.7 | J7: 3 | K7: 3 | L7: 3 | M7: 3 | N7: 0.2 | O7: =IF($B7="","",MIN(D7,E7)) -> 15 | P7: =IF($B7="","",0.075*C7^0.75) -> 0.83852549 | Q7: =IF($B7="","",IF(MIN(1,(L7*M7)/(J7*K7))>=0.999,0,MIN(1,(L7*M7)/(J7*K7)))) -> 0 | R7: =IF($B7="","",Q7/(B7+Q7)) -> 0 | S7: =IF($B7="","",P7*SQRT(9.81/C7)) -> 0.52526779 | T7: =IF($B7="","",(F7*G7^3/(H7*I7^3))*(O7/C7)^3) -> 0.23318284 | U7: =IF($B7="","",(C7/O7)*(1-R7)) -> 1.6666667 | V7: =IF($B7="","",Equations!$C$6+Equations!$C$7*S7+Equations!$C$8*T7+Equations!$C$9*U7+Equations!$C$10*S7^2+Equations!$C$11*S7*T7+Equations!$C$12*S7*U7+Equations!$C$13*T7^2+Equations!$C$14*T7*U7+Equations!$C$15*U7^2) -> 0.10701062 | W7: =IF($B7="","",Equations!$D$6+Equations!$D$7*S7+Equations!$D$8*T7+Equations!$D$10*S7^2+Equations!$D$11*S7*T7+Equations!$D$13*T7^2) -> 0.39631035 | X7: =IF($B7="","",Equations!$E$6+Equations!$E$8*T7+Equations!$E$10*S7^2+Equations!$E$11*S7*T7+Equations!$E$13*T7^2+Equations!$E$15*U7^2) -> 1.194889 | Y7: =IF($B7="","",Equations!$F$6+Equations!$F$10*S7^2+Equations!$F$11*S7*T7) -> 2.2271846 | Z7: =IF($B7="","",IF(AND(S7>=0.174,S7<=1.486,T7>=0,T7<=13.05,U7>=0.25,U7<=4.55,B7>=1,B7<=10),"In range","Extrapolation")) -> In range | AA7: =IF($B7="","",IF(MIN(V7:Y7)<=0,"Fail (<0)","Pass")) -> Pass | AB7: =IF($B7="","",IF(AND(V7<=W7,W7<=X7,X7<=Y7),"Pass","Fail")) -> Pass | AC7: =IF($B7="","",IF(OR(V7<=0,W7<=0,V7>W7),"Cannot classify",IF(N7<V7,"Low",IF(N7<W7,"Moderate","High")))) -> Moderate
A8: Example D | B8: 2 | C8: 7 | D8: 10 | E8: 12 | F8: 0.3 | G8: 0.3 | H8: 0.25 | I8: 0.6 | J8: 2 | K8: 3 | L8: 2 | M8: 3 | N8: 0.4 | O8: =IF($B8="","",MIN(D8,E8)) -> 10 | P8: =IF($B8="","",0.075*C8^0.75) -> 0.32276378 | Q8: =IF($B8="","",IF(MIN(1,(L8*M8)/(J8*K8))>=0.999,0,MIN(1,(L8*M8)/(J8*K8)))) -> 0 | R8: =IF($B8="","",Q8/(B8+Q8)) -> 0 | S8: =IF($B8="","",P8*SQRT(9.81/C8)) -> 0.38209405 | T8: =IF($B8="","",(F8*G8^3/(H8*I8^3))*(O8/C8)^3) -> 0.43731778 | U8: =IF($B8="","",(C8/O8)*(1-R8)) -> 0.7 | V8: =IF($B8="","",Equations!$C$6+Equations!$C$7*S8+Equations!$C$8*T8+Equations!$C$9*U8+Equations!$C$10*S8^2+Equations!$C$11*S8*T8+Equations!$C$12*S8*U8+Equations!$C$13*T8^2+Equations!$C$14*T8*U8+Equations!$C$15*U8^2) -> 0.22642161 | W8: =IF($B8="","",Equations!$D$6+Equations!$D$7*S8+Equations!$D$8*T8+Equations!$D$10*S8^2+Equations!$D$11*S8*T8+Equations!$D$13*T8^2) -> 0.5824208 | X8: =IF($B8="","",Equations!$E$6+Equations!$E$8*T8+Equations!$E$10*S8^2+Equations!$E$11*S8*T8+Equations!$E$13*T8^2+Equations!$E$15*U8^2) -> 1.3261678 | Y8: =IF($B8="","",Equations!$F$6+Equations!$F$10*S8^2+Equations!$F$11*S8*T8) -> 2.3891316 | Z8: =IF($B8="","",IF(AND(S8>=0.174,S8<=1.486,T8>=0,T8<=13.05,U8>=0.25,U8<=4.55,B8>=1,B8<=10),"In range","Extrapolation")) -> In range | AA8: =IF($B8="","",IF(MIN(V8:Y8)<=0,"Fail (<0)","Pass")) -> Pass | AB8: =IF($B8="","",IF(AND(V8<=W8,W8<=X8,X8<=Y8),"Pass","Fail")) -> Pass | AC8: =IF($B8="","",IF(OR(V8<=0,W8<=0,V8>W8),"Cannot classify",IF(N8<V8,"Low",IF(N8<W8,"Moderate","High")))) -> Moderate
O9: =IF($B9="","",MIN(D9,E9)) | P9: =IF($B9="","",0.075*C9^0.75) | Q9: =IF($B9="","",IF(MIN(1,(L9*M9)/(J9*K9))>=0.999,0,MIN(1,(L9*M9)/(J9*K9)))) | R9: =IF($B9="","",Q9/(B9+Q9)) | S9: =IF($B9="","",P9*SQRT(9.81/C9)) | T9: =IF($B9="","",(F9*G9^3/(H9*I9^3))*(O9/C9)^3) | U9: =IF($B9="","",(C9/O9)*(1-R9)) | V9: =IF($B9="","",Equations!$C$6+Equations!$C$7*S9+Equations!$C$8*T9+Equations!$C$9*U9+Equations!$C$10*S9^2+Equations!$C$11*S9*T9+Equations!$C$12*S9*U9+Equations!$C$13*T9^2+Equations!$C$14*T9*U9+Equations!$C$15*U9^2) | W9: =IF($B9="","",Equations!$D$6+Equations!$D$7*S9+Equations!$D$8*T9+Equations!$D$10*S9^2+Equations!$D$11*S9*T9+Equations!$D$13*T9^2) | X9: =IF($B9="","",Equations!$E$6+Equations!$E$8*T9+Equations!$E$10*S9^2+Equations!$E$11*S9*T9+Equations!$E$13*T9^2+Equations!$E$15*U9^2) | Y9: =IF($B9="","",Equations!$F$6+Equations!$F$10*S9^2+Equations!$F$11*S9*T9) | Z9: =IF($B9="","",IF(AND(S9>=0.174,S9<=1.486,T9>=0,T9<=13.05,U9>=0.25,U9<=4.55,B9>=1,B9<=10),"In range","Extrapolation")) | AA9: =IF($B9="","",IF(MIN(V9:Y9)<=0,"Fail (<0)","Pass")) | AB9: =IF($B9="","",IF(AND(V9<=W9,W9<=X9,X9<=Y9),"Pass","Fail")) | AC9: =IF($B9="","",IF(OR(V9<=0,W9<=0,V9>W9),"Cannot classify",IF(N9<V9,"Low",IF(N9<W9,"Moderate","High"))))
O10: =IF($B10="","",MIN(D10,E10)) | P10: =IF($B10="","",0.075*C10^0.75) | Q10: =IF($B10="","",IF(MIN(1,(L10*M10)/(J10*K10))>=0.999,0,MIN(1,(L10*M10)/(J10*K10)))) | R10: =IF($B10="","",Q10/(B10+Q10)) | S10: =IF($B10="","",P10*SQRT(9.81/C10)) | T10: =IF($B10="","",(F10*G10^3/(H10*I10^3))*(O10/C10)^3) | U10: =IF($B10="","",(C10/O10)*(1-R10)) | V10: =IF($B10="","",Equations!$C$6+Equations!$C$7*S10+Equations!$C$8*T10+Equations!$C$9*U10+Equations!$C$10*S10^2+Equations!$C$11*S10*T10+Equations!$C$12*S10*U10+Equations!$C$13*T10^2+Equations!$C$14*T10*U10+Equations!$C$15*U10^2) | W10: =IF($B10="","",Equations!$D$6+Equations!$D$7*S10+Equations!$D$8*T10+Equations!$D$10*S10^2+Equations!$D$11*S10*T10+Equations!$D$13*T10^2) | X10: =IF($B10="","",Equations!$E$6+Equations!$E$8*T10+Equations!$E$10*S10^2+Equations!$E$11*S10*T10+Equations!$E$13*T10^2+Equations!$E$15*U10^2) | Y10: =IF($B10="","",Equations!$F$6+Equations!$F$10*S10^2+Equations!$F$11*S10*T10) | Z10: =IF($B10="","",IF(AND(S10>=0.174,S10<=1.486,T10>=0,T10<=13.05,U10>=0.25,U10<=4.55,B10>=1,B10<=10),"In range","Extrapolation")) | AA10: =IF($B10="","",IF(MIN(V10:Y10)<=0,"Fail (<0)","Pass")) | AB10: =IF($B10="","",IF(AND(V10<=W10,W10<=X10,X10<=Y10),"Pass","Fail")) | AC10: =IF($B10="","",IF(OR(V10<=0,W10<=0,V10>W10),"Cannot classify",IF(N10<V10,"Low",IF(N10<W10,"Moderate","High"))))
O11: =IF($B11="","",MIN(D11,E11)) | P11: =IF($B11="","",0.075*C11^0.75) | Q11: =IF($B11="","",IF(MIN(1,(L11*M11)/(J11*K11))>=0.999,0,MIN(1,(L11*M11)/(J11*K11)))) | R11: =IF($B11="","",Q11/(B11+Q11)) | S11: =IF($B11="","",P11*SQRT(9.81/C11)) | T11: =IF($B11="","",(F11*G11^3/(H11*I11^3))*(O11/C11)^3) | U11: =IF($B11="","",(C11/O11)*(1-R11)) | V11: =IF($B11="","",Equations!$C$6+Equations!$C$7*S11+Equations!$C$8*T11+Equations!$C$9*U11+Equations!$C$10*S11^2+Equations!$C$11*S11*T11+Equations!$C$12*S11*U11+Equations!$C$13*T11^2+Equations!$C$14*T11*U11+Equations!$C$15*U11^2) | W11: =IF($B11="","",Equations!$D$6+Equations!$D$7*S11+Equations!$D$8*T11+Equations!$D$10*S11^2+Equations!$D$11*S11*T11+Equations!$D$13*T11^2) | X11: =IF($B11="","",Equations!$E$6+Equations!$E$8*T11+Equations!$E$10*S11^2+Equations!$E$11*S11*T11+Equations!$E$13*T11^2+Equations!$E$15*U11^2) | Y11: =IF($B11="","",Equations!$F$6+Equations!$F$10*S11^2+Equations!$F$11*S11*T11) | Z11: =IF($B11="","",IF(AND(S11>=0.174,S11<=1.486,T11>=0,T11<=13.05,U11>=0.25,U11<=4.55,B11>=1,B11<=10),"In range","Extrapolation")) | AA11: =IF($B11="","",IF(MIN(V11:Y11)<=0,"Fail (<0)","Pass")) | AB11: =IF($B11="","",IF(AND(V11<=W11,W11<=X11,X11<=Y11),"Pass","Fail")) | AC11: =IF($B11="","",IF(OR(V11<=0,W11<=0,V11>W11),"Cannot classify",IF(N11<V11,"Low",IF(N11<W11,"Moderate","High"))))
O12: =IF($B12="","",MIN(D12,E12)) | P12: =IF($B12="","",0.075*C12^0.75) | Q12: =IF($B12="","",IF(MIN(1,(L12*M12)/(J12*K12))>=0.999,0,MIN(1,(L12*M12)/(J12*K12)))) | R12: =IF($B12="","",Q12/(B12+Q12)) | S12: =IF($B12="","",P12*SQRT(9.81/C12)) | T12: =IF($B12="","",(F12*G12^3/(H12*I12^3))*(O12/C12)^3) | U12: =IF($B12="","",(C12/O12)*(1-R12)) | V12: =IF($B12="","",Equations!$C$6+Equations!$C$7*S12+Equations!$C$8*T12+Equations!$C$9*U12+Equations!$C$10*S12^2+Equations!$C$11*S12*T12+Equations!$C$12*S12*U12+Equations!$C$13*T12^2+Equations!$C$14*T12*U12+Equations!$C$15*U12^2) | W12: =IF($B12="","",Equations!$D$6+Equations!$D$7*S12+Equations!$D$8*T12+Equations!$D$10*S12^2+Equations!$D$11*S12*T12+Equations!$D$13*T12^2) | X12: =IF($B12="","",Equations!$E$6+Equations!$E$8*T12+Equations!$E$10*S12^2+Equations!$E$11*S12*T12+Equations!$E$13*T12^2+Equations!$E$15*U12^2) | Y12: =IF($B12="","",Equations!$F$6+Equations!$F$10*S12^2+Equations!$F$11*S12*T12) | Z12: =IF($B12="","",IF(AND(S12>=0.174,S12<=1.486,T12>=0,T12<=13.05,U12>=0.25,U12<=4.55,B12>=1,B12<=10),"In range","Extrapolation")) | AA12: =IF($B12="","",IF(MIN(V12:Y12)<=0,"Fail (<0)","Pass")) | AB12: =IF($B12="","",IF(AND(V12<=W12,W12<=X12,X12<=Y12),"Pass","Fail")) | AC12: =IF($B12="","",IF(OR(V12<=0,W12<=0,V12>W12),"Cannot classify",IF(N12<V12,"Low",IF(N12<W12,"Moderate","High"))))
O13: =IF($B13="","",MIN(D13,E13)) | P13: =IF($B13="","",0.075*C13^0.75) | Q13: =IF($B13="","",IF(MIN(1,(L13*M13)/(J13*K13))>=0.999,0,MIN(1,(L13*M13)/(J13*K13)))) | R13: =IF($B13="","",Q13/(B13+Q13)) | S13: =IF($B13="","",P13*SQRT(9.81/C13)) | T13: =IF($B13="","",(F13*G13^3/(H13*I13^3))*(O13/C13)^3) | U13: =IF($B13="","",(C13/O13)*(1-R13)) | V13: =IF($B13="","",Equations!$C$6+Equations!$C$7*S13+Equations!$C$8*T13+Equations!$C$9*U13+Equations!$C$10*S13^2+Equations!$C$11*S13*T13+Equations!$C$12*S13*U13+Equations!$C$13*T13^2+Equations!$C$14*T13*U13+Equations!$C$15*U13^2) | W13: =IF($B13="","",Equations!$D$6+Equations!$D$7*S13+Equations!$D$8*T13+Equations!$D$10*S13^2+Equations!$D$11*S13*T13+Equations!$D$13*T13^2) | X13: =IF($B13="","",Equations!$E$6+Equations!$E$8*T13+Equations!$E$10*S13^2+Equations!$E$11*S13*T13+Equations!$E$13*T13^2+Equations!$E$15*U13^2) | Y13: =IF($B13="","",Equations!$F$6+Equations!$F$10*S13^2+Equations!$F$11*S13*T13) | Z13: =IF($B13="","",IF(AND(S13>=0.174,S13<=1.486,T13>=0,T13<=13.05,U13>=0.25,U13<=4.55,B13>=1,B13<=10),"In range","Extrapolation")) | AA13: =IF($B13="","",IF(MIN(V13:Y13)<=0,"Fail (<0)","Pass")) | AB13: =IF($B13="","",IF(AND(V13<=W13,W13<=X13,X13<=Y13),"Pass","Fail")) | AC13: =IF($B13="","",IF(OR(V13<=0,W13<=0,V13>W13),"Cannot classify",IF(N13<V13,"Low",IF(N13<W13,"Moderate","High"))))
O14: =IF($B14="","",MIN(D14,E14)) | P14: =IF($B14="","",0.075*C14^0.75) | Q14: =IF($B14="","",IF(MIN(1,(L14*M14)/(J14*K14))>=0.999,0,MIN(1,(L14*M14)/(J14*K14)))) | R14: =IF($B14="","",Q14/(B14+Q14)) | S14: =IF($B14="","",P14*SQRT(9.81/C14)) | T14: =IF($B14="","",(F14*G14^3/(H14*I14^3))*(O14/C14)^3) | U14: =IF($B14="","",(C14/O14)*(1-R14)) | V14: =IF($B14="","",Equations!$C$6+Equations!$C$7*S14+Equations!$C$8*T14+Equations!$C$9*U14+Equations!$C$10*S14^2+Equations!$C$11*S14*T14+Equations!$C$12*S14*U14+Equations!$C$13*T14^2+Equations!$C$14*T14*U14+Equations!$C$15*U14^2) | W14: =IF($B14="","",Equations!$D$6+Equations!$D$7*S14+Equations!$D$8*T14+Equations!$D$10*S14^2+Equations!$D$11*S14*T14+Equations!$D$13*T14^2) | X14: =IF($B14="","",Equations!$E$6+Equations!$E$8*T14+Equations!$E$10*S14^2+Equations!$E$11*S14*T14+Equations!$E$13*T14^2+Equations!$E$15*U14^2) | Y14: =IF($B14="","",Equations!$F$6+Equations!$F$10*S14^2+Equations!$F$11*S14*T14) | Z14: =IF($B14="","",IF(AND(S14>=0.174,S14<=1.486,T14>=0,T14<=13.05,U14>=0.25,U14<=4.55,B14>=1,B14<=10),"In range","Extrapolation")) | AA14: =IF($B14="","",IF(MIN(V14:Y14)<=0,"Fail (<0)","Pass")) | AB14: =IF($B14="","",IF(AND(V14<=W14,W14<=X14,X14<=Y14),"Pass","Fail")) | AC14: =IF($B14="","",IF(OR(V14<=0,W14<=0,V14>W14),"Cannot classify",IF(N14<V14,"Low",IF(N14<W14,"Moderate","High"))))
O15: =IF($B15="","",MIN(D15,E15)) | P15: =IF($B15="","",0.075*C15^0.75) | Q15: =IF($B15="","",IF(MIN(1,(L15*M15)/(J15*K15))>=0.999,0,MIN(1,(L15*M15)/(J15*K15)))) | R15: =IF($B15="","",Q15/(B15+Q15)) | S15: =IF($B15="","",P15*SQRT(9.81/C15)) | T15: =IF($B15="","",(F15*G15^3/(H15*I15^3))*(O15/C15)^3) | U15: =IF($B15="","",(C15/O15)*(1-R15)) | V15: =IF($B15="","",Equations!$C$6+Equations!$C$7*S15+Equations!$C$8*T15+Equations!$C$9*U15+Equations!$C$10*S15^2+Equations!$C$11*S15*T15+Equations!$C$12*S15*U15+Equations!$C$13*T15^2+Equations!$C$14*T15*U15+Equations!$C$15*U15^2) | W15: =IF($B15="","",Equations!$D$6+Equations!$D$7*S15+Equations!$D$8*T15+Equations!$D$10*S15^2+Equations!$D$11*S15*T15+Equations!$D$13*T15^2) | X15: =IF($B15="","",Equations!$E$6+Equations!$E$8*T15+Equations!$E$10*S15^2+Equations!$E$11*S15*T15+Equations!$E$13*T15^2+Equations!$E$15*U15^2) | Y15: =IF($B15="","",Equations!$F$6+Equations!$F$10*S15^2+Equations!$F$11*S15*T15) | Z15: =IF($B15="","",IF(AND(S15>=0.174,S15<=1.486,T15>=0,T15<=13.05,U15>=0.25,U15<=4.55,B15>=1,B15<=10),"In range","Extrapolation")) | AA15: =IF($B15="","",IF(MIN(V15:Y15)<=0,"Fail (<0)","Pass")) | AB15: =IF($B15="","",IF(AND(V15<=W15,W15<=X15,X15<=Y15),"Pass","Fail")) | AC15: =IF($B15="","",IF(OR(V15<=0,W15<=0,V15>W15),"Cannot classify",IF(N15<V15,"Low",IF(N15<W15,"Moderate","High"))))
O16: =IF($B16="","",MIN(D16,E16)) | P16: =IF($B16="","",0.075*C16^0.75) | Q16: =IF($B16="","",IF(MIN(1,(L16*M16)/(J16*K16))>=0.999,0,MIN(1,(L16*M16)/(J16*K16)))) | R16: =IF($B16="","",Q16/(B16+Q16)) | S16: =IF($B16="","",P16*SQRT(9.81/C16)) | T16: =IF($B16="","",(F16*G16^3/(H16*I16^3))*(O16/C16)^3) | U16: =IF($B16="","",(C16/O16)*(1-R16)) | V16: =IF($B16="","",Equations!$C$6+Equations!$C$7*S16+Equations!$C$8*T16+Equations!$C$9*U16+Equations!$C$10*S16^2+Equations!$C$11*S16*T16+Equations!$C$12*S16*U16+Equations!$C$13*T16^2+Equations!$C$14*T16*U16+Equations!$C$15*U16^2) | W16: =IF($B16="","",Equations!$D$6+Equations!$D$7*S16+Equations!$D$8*T16+Equations!$D$10*S16^2+Equations!$D$11*S16*T16+Equations!$D$13*T16^2) | X16: =IF($B16="","",Equations!$E$6+Equations!$E$8*T16+Equations!$E$10*S16^2+Equations!$E$11*S16*T16+Equations!$E$13*T16^2+Equations!$E$15*U16^2) | Y16: =IF($B16="","",Equations!$F$6+Equations!$F$10*S16^2+Equations!$F$11*S16*T16) | Z16: =IF($B16="","",IF(AND(S16>=0.174,S16<=1.486,T16>=0,T16<=13.05,U16>=0.25,U16<=4.55,B16>=1,B16<=10),"In range","Extrapolation")) | AA16: =IF($B16="","",IF(MIN(V16:Y16)<=0,"Fail (<0)","Pass")) | AB16: =IF($B16="","",IF(AND(V16<=W16,W16<=X16,X16<=Y16),"Pass","Fail")) | AC16: =IF($B16="","",IF(OR(V16<=0,W16<=0,V16>W16),"Cannot classify",IF(N16<V16,"Low",IF(N16<W16,"Moderate","High"))))
O17: =IF($B17="","",MIN(D17,E17)) | P17: =IF($B17="","",0.075*C17^0.75) | Q17: =IF($B17="","",IF(MIN(1,(L17*M17)/(J17*K17))>=0.999,0,MIN(1,(L17*M17)/(J17*K17)))) | R17: =IF($B17="","",Q17/(B17+Q17)) | S17: =IF($B17="","",P17*SQRT(9.81/C17)) | T17: =IF($B17="","",(F17*G17^3/(H17*I17^3))*(O17/C17)^3) | U17: =IF($B17="","",(C17/O17)*(1-R17)) | V17: =IF($B17="","",Equations!$C$6+Equations!$C$7*S17+Equations!$C$8*T17+Equations!$C$9*U17+Equations!$C$10*S17^2+Equations!$C$11*S17*T17+Equations!$C$12*S17*U17+Equations!$C$13*T17^2+Equations!$C$14*T17*U17+Equations!$C$15*U17^2) | W17: =IF($B17="","",Equations!$D$6+Equations!$D$7*S17+Equations!$D$8*T17+Equations!$D$10*S17^2+Equations!$D$11*S17*T17+Equations!$D$13*T17^2) | X17: =IF($B17="","",Equations!$E$6+Equations!$E$8*T17+Equations!$E$10*S17^2+Equations!$E$11*S17*T17+Equations!$E$13*T17^2+Equations!$E$15*U17^2) | Y17: =IF($B17="","",Equations!$F$6+Equations!$F$10*S17^2+Equations!$F$11*S17*T17) | Z17: =IF($B17="","",IF(AND(S17>=0.174,S17<=1.486,T17>=0,T17<=13.05,U17>=0.25,U17<=4.55,B17>=1,B17<=10),"In range","Extrapolation")) | AA17: =IF($B17="","",IF(MIN(V17:Y17)<=0,"Fail (<0)","Pass")) | AB17: =IF($B17="","",IF(AND(V17<=W17,W17<=X17,X17<=Y17),"Pass","Fail")) | AC17: =IF($B17="","",IF(OR(V17<=0,W17<=0,V17>W17),"Cannot classify",IF(N17<V17,"Low",IF(N17<W17,"Moderate","High"))))
O18: =IF($B18="","",MIN(D18,E18)) | P18: =IF($B18="","",0.075*C18^0.75) | Q18: =IF($B18="","",IF(MIN(1,(L18*M18)/(J18*K18))>=0.999,0,MIN(1,(L18*M18)/(J18*K18)))) | R18: =IF($B18="","",Q18/(B18+Q18)) | S18: =IF($B18="","",P18*SQRT(9.81/C18)) | T18: =IF($B18="","",(F18*G18^3/(H18*I18^3))*(O18/C18)^3) | U18: =IF($B18="","",(C18/O18)*(1-R18)) | V18: =IF($B18="","",Equations!$C$6+Equations!$C$7*S18+Equations!$C$8*T18+Equations!$C$9*U18+Equations!$C$10*S18^2+Equations!$C$11*S18*T18+Equations!$C$12*S18*U18+Equations!$C$13*T18^2+Equations!$C$14*T18*U18+Equations!$C$15*U18^2) | W18: =IF($B18="","",Equations!$D$6+Equations!$D$7*S18+Equations!$D$8*T18+Equations!$D$10*S18^2+Equations!$D$11*S18*T18+Equations!$D$13*T18^2) | X18: =IF($B18="","",Equations!$E$6+Equations!$E$8*T18+Equations!$E$10*S18^2+Equations!$E$11*S18*T18+Equations!$E$13*T18^2+Equations!$E$15*U18^2) | Y18: =IF($B18="","",Equations!$F$6+Equations!$F$10*S18^2+Equations!$F$11*S18*T18) | Z18: =IF($B18="","",IF(AND(S18>=0.174,S18<=1.486,T18>=0,T18<=13.05,U18>=0.25,U18<=4.55,B18>=1,B18<=10),"In range","Extrapolation")) | AA18: =IF($B18="","",IF(MIN(V18:Y18)<=0,"Fail (<0)","Pass")) | AB18: =IF($B18="","",IF(AND(V18<=W18,W18<=X18,X18<=Y18),"Pass","Fail")) | AC18: =IF($B18="","",IF(OR(V18<=0,W18<=0,V18>W18),"Cannot classify",IF(N18<V18,"Low",IF(N18<W18,"Moderate","High"))))
O19: =IF($B19="","",MIN(D19,E19)) | P19: =IF($B19="","",0.075*C19^0.75) | Q19: =IF($B19="","",IF(MIN(1,(L19*M19)/(J19*K19))>=0.999,0,MIN(1,(L19*M19)/(J19*K19)))) | R19: =IF($B19="","",Q19/(B19+Q19)) | S19: =IF($B19="","",P19*SQRT(9.81/C19)) | T19: =IF($B19="","",(F19*G19^3/(H19*I19^3))*(O19/C19)^3) | U19: =IF($B19="","",(C19/O19)*(1-R19)) | V19: =IF($B19="","",Equations!$C$6+Equations!$C$7*S19+Equations!$C$8*T19+Equations!$C$9*U19+Equations!$C$10*S19^2+Equations!$C$11*S19*T19+Equations!$C$12*S19*U19+Equations!$C$13*T19^2+Equations!$C$14*T19*U19+Equations!$C$15*U19^2) | W19: =IF($B19="","",Equations!$D$6+Equations!$D$7*S19+Equations!$D$8*T19+Equations!$D$10*S19^2+Equations!$D$11*S19*T19+Equations!$D$13*T19^2) | X19: =IF($B19="","",Equations!$E$6+Equations!$E$8*T19+Equations!$E$10*S19^2+Equations!$E$11*S19*T19+Equations!$E$13*T19^2+Equations!$E$15*U19^2) | Y19: =IF($B19="","",Equations!$F$6+Equations!$F$10*S19^2+Equations!$F$11*S19*T19) | Z19: =IF($B19="","",IF(AND(S19>=0.174,S19<=1.486,T19>=0,T19<=13.05,U19>=0.25,U19<=4.55,B19>=1,B19<=10),"In range","Extrapolation")) | AA19: =IF($B19="","",IF(MIN(V19:Y19)<=0,"Fail (<0)","Pass")) | AB19: =IF($B19="","",IF(AND(V19<=W19,W19<=X19,X19<=Y19),"Pass","Fail")) | AC19: =IF($B19="","",IF(OR(V19<=0,W19<=0,V19>W19),"Cannot classify",IF(N19<V19,"Low",IF(N19<W19,"Moderate","High"))))
O20: =IF($B20="","",MIN(D20,E20)) | P20: =IF($B20="","",0.075*C20^0.75) | Q20: =IF($B20="","",IF(MIN(1,(L20*M20)/(J20*K20))>=0.999,0,MIN(1,(L20*M20)/(J20*K20)))) | R20: =IF($B20="","",Q20/(B20+Q20)) | S20: =IF($B20="","",P20*SQRT(9.81/C20)) | T20: =IF($B20="","",(F20*G20^3/(H20*I20^3))*(O20/C20)^3) | U20: =IF($B20="","",(C20/O20)*(1-R20)) | V20: =IF($B20="","",Equations!$C$6+Equations!$C$7*S20+Equations!$C$8*T20+Equations!$C$9*U20+Equations!$C$10*S20^2+Equations!$C$11*S20*T20+Equations!$C$12*S20*U20+Equations!$C$13*T20^2+Equations!$C$14*T20*U20+Equations!$C$15*U20^2) | W20: =IF($B20="","",Equations!$D$6+Equations!$D$7*S20+Equations!$D$8*T20+Equations!$D$10*S20^2+Equations!$D$11*S20*T20+Equations!$D$13*T20^2) | X20: =IF($B20="","",Equations!$E$6+Equations!$E$8*T20+Equations!$E$10*S20^2+Equations!$E$11*S20*T20+Equations!$E$13*T20^2+Equations!$E$15*U20^2) | Y20: =IF($B20="","",Equations!$F$6+Equations!$F$10*S20^2+Equations!$F$11*S20*T20) | Z20: =IF($B20="","",IF(AND(S20>=0.174,S20<=1.486,T20>=0,T20<=13.05,U20>=0.25,U20<=4.55,B20>=1,B20<=10),"In range","Extrapolation")) | AA20: =IF($B20="","",IF(MIN(V20:Y20)<=0,"Fail (<0)","Pass")) | AB20: =IF($B20="","",IF(AND(V20<=W20,W20<=X20,X20<=Y20),"Pass","Fail")) | AC20: =IF($B20="","",IF(OR(V20<=0,W20<=0,V20>W20),"Cannot classify",IF(N20<V20,"Low",IF(N20<W20,"Moderate","High"))))
... O44: =IF($B44="","",MIN(D44,E44)) | P44: =IF($B44="","",0.075*C44^0.75) | Q44: =IF($B44="","",IF(MIN(1,(L44*M44)/(J44*K44))>=0.999,0,MIN(1,(L44*M44)/(J44*K44)))) | R44: =IF($B44="","",Q44/(B44+Q44)) | S44: =IF($B44="","",P44*SQRT(9.81/C44)) | T44: =IF($B44="","",(F44*G44^3/(H44*I44^3))*(O44/C44)^3) | U44: =IF($B44="","",(C44/O44)*(1-R44)) | V44: =IF($B44="","",Equations!$C$6+Equations!$C$7*S44+Equations!$C$8*T44+Equations!$C$9*U44+Equations!$C$10*S44^2+Equations!$C$11*S44*T44+Equations!$C$12*S44*U44+Equations!$C$13*T44^2+Equations!$C$14*T44*U44+Equations!$C$15*U44^2) | W44: =IF($B44="","",Equations!$D$6+Equations!$D$7*S44+Equations!$D$8*T44+Equations!$D$10*S44^2+Equations!$D$11*S44*T44+Equations!$D$13*T44^2) | X44: =IF($B44="","",Equations!$E$6+Equations!$E$8*T44+Equations!$E$10*S44^2+Equations!$E$11*S44*T44+Equations!$E$13*T44^2+Equations!$E$15*U44^2) | Y44: =IF($B44="","",Equations!$F$6+Equations!$F$10*S44^2+Equations!$F$11*S44*T44) | Z44: =IF($B44="","",IF(AND(S44>=0.174,S44<=1.486,T44>=0,T44<=13.05,U44>=0.25,U44<=4.55,B44>=1,B44<=10),"In range","Extrapolation")) | AA44: =IF($B44="","",IF(MIN(V44:Y44)<=0,"Fail (<0)","Pass")) | AB44: =IF($B44="","",IF(AND(V44<=W44,W44<=X44,X44<=Y44),"Pass","Fail")) | AC44: =IF($B44="","",IF(OR(V44<=0,W44<=0,V44>W44),"Cannot classify",IF(N44<V44,"Low",IF(N44<W44,"Moderate","High"))))

Sheet Verification
A1: VERIFICATION · external pool (Tables A.16 and A.17) recomputed with this workbook's equations
A2: Inputs and published/paper-predicted medians transcribed from Tables A.16–A.17 (g). "This workbook" uses the Equations sheet with the 0.01 g floor. Δ = difference from the paper's prediction; ±0.001–0.004 g reflects rounding of T̄ in Table A.16. Four rows where the two tables disagree are noted in column R. * = transparency only, not transferability evidence.
A4: # | B4: Study | C4: Applicability group | D4: N | E4: H (m) | F4: B (m) | G4: T̄ | H4: λeff | I4: SR | J4: DS1 published | K4: DS1 paper pred. | L4: DS1 this workbook | M4: Δ vs paper | N4: DS2 published | O4: DS2 paper pred. | P4: DS2 this workbook | Q4: Δ vs paper | R4: Transcription note
A5: 1 | B5: Rosti et al. | C5: Compatible-Empirical | D5: 2 | E5: 6 | F5: 4.9 | G5: 0.368 | H5: 1.225 | I5: 1 | J5: 0.192 | K5: 0.259 | L5: =MAX(0.01,Equations!$C$6+Equations!$C$7*G5+Equations!$C$8*I5+Equations!$C$9*H5+Equations!$C$10*G5^2+Equations!$C$11*G5*I5+Equations!$C$12*G5*H5+Equations!$C$13*I5^2+Equations!$C$14*I5*H5+Equations!$C$15*H5^2) -> 0.25926078 | M5: =L5-K5 -> 0.0002607839 | N5: 0.501 | O5: 0.674 | P5: =MAX(0.01,Equations!$D$6+Equations!$D$7*G5+Equations!$D$8*I5+Equations!$D$10*G5^2+Equations!$D$11*G5*I5+Equations!$D$13*I5^2) -> 0.67337539 | Q5: =P5-O5 -> -0.000624608
A6: 2 | B6: Rosti et al. | C6: Compatible-Empirical | D6: 4 | E6: 12 | F6: 4.9 | G6: 0.437 | H6: 1.732 | I6: 1 | J6: 0.113 | K6: 0.194 | L6: =MAX(0.01,Equations!$C$6+Equations!$C$7*G6+Equations!$C$8*I6+Equations!$C$9*H6+Equations!$C$10*G6^2+Equations!$C$11*G6*I6+Equations!$C$12*G6*H6+Equations!$C$13*I6^2+Equations!$C$14*I6*H6+Equations!$C$15*H6^2) -> 0.19426399 | M6: =L6-K6 -> 0.0002639902 | N6: 0.223 | O6: 0.585 | P6: =MAX(0.01,Equations!$D$6+Equations!$D$7*G6+Equations!$D$8*I6+Equations!$D$10*G6^2+Equations!$D$11*G6*I6+Equations!$D$13*I6^2) -> 0.58501934 | Q6: =P6-O6 -> 1.93395e-05
A7: 3 | B7: Rosti et al. | C7: Compatible-Empirical | D7: 6 | E7: 18 | F7: 8.5 | G7: 0.484 | H7: 1.221 | I7: 1 | J7: 0.073 | K7: 0.152 | L7: =MAX(0.01,Equations!$C$6+Equations!$C$7*G7+Equations!$C$8*I7+Equations!$C$9*H7+Equations!$C$10*G7^2+Equations!$C$11*G7*I7+Equations!$C$12*G7*H7+Equations!$C$13*I7^2+Equations!$C$14*I7*H7+Equations!$C$15*H7^2) -> 0.20115502 | M7: =L7-K7 -> 0.049155018 | N7: 0.16 | O7: 0.53 | P7: =MAX(0.01,Equations!$D$6+Equations!$D$7*G7+Equations!$D$8*I7+Equations!$D$10*G7^2+Equations!$D$11*G7*I7+Equations!$D$13*I7^2) -> 0.53026225 | Q7: =P7-O7 -> 0.000262248 | R7: A.16 inputs do not reproduce the A.17 prediction (λeff 1.221 looks inconsistent with H/B = 2.12).
A8: 4 | B8: Rosti et al. | C8: Compatible-Empirical | D8: 2 | E8: 6 | F8: 4.9 | G8: 0.368 | H8: 1.225 | I8: 2 | J8: 0.316 | K8: 0.347 | L8: =MAX(0.01,Equations!$C$6+Equations!$C$7*G8+Equations!$C$8*I8+Equations!$C$9*H8+Equations!$C$10*G8^2+Equations!$C$11*G8*I8+Equations!$C$12*G8*H8+Equations!$C$13*I8^2+Equations!$C$14*I8*H8+Equations!$C$15*H8^2) -> 0.34689218 | M8: =L8-K8 -> -0.0001078161 | N8: 0.565 | O8: 0.799 | P8: =MAX(0.01,Equations!$D$6+Equations!$D$7*G8+Equations!$D$8*I8+Equations!$D$10*G8^2+Equations!$D$11*G8*I8+Equations!$D$13*I8^2) -> 0.79807939 | Q8: =P8-O8 -> -0.000920608
A9: 5 | B9: Rosti et al. | C9: Compatible-Empirical | D9: 4 | E9: 12 | F9: 4.9 | G9: 0.437 | H9: 1.299 | I9: 2 | J9: 0.207 | K9: 0.298 | L9: =MAX(0.01,Equations!$C$6+Equations!$C$7*G9+Equations!$C$8*I9+Equations!$C$9*H9+Equations!$C$10*G9^2+Equations!$C$11*G9*I9+Equations!$C$12*G9*H9+Equations!$C$13*I9^2+Equations!$C$14*I9*H9+Equations!$C$15*H9^2) -> 0.29809726 | M9: =L9-K9 -> 9.72561e-05 | N9: 0.424 | O9: 0.704 | P9: =MAX(0.01,Equations!$D$6+Equations!$D$7*G9+Equations!$D$8*I9+Equations!$D$10*G9^2+Equations!$D$11*G9*I9+Equations!$D$13*I9^2) -> 0.70389284 | Q9: =P9-O9 -> -0.0001071605
A10: 6 | B10: Rosti et al. | C10: Compatible-Empirical | D10: 6 | E10: 18 | F10: 8.5 | G10: 0.484 | H10: 1.767 | I10: 2 | J10: 0.186 | K10: 0.234 | L10: =MAX(0.01,Equations!$C$6+Equations!$C$7*G10+Equations!$C$8*I10+Equations!$C$9*H10+Equations!$C$10*G10^2+Equations!$C$11*G10*I10+Equations!$C$12*G10*H10+Equations!$C$13*I10^2+Equations!$C$14*I10*H10+Equations!$C$15*H10^2) -> 0.23395829 | M10: =L10-K10 -> -4.17121e-05 | N10: 0.306 | O10: 0.645 | P10: =MAX(0.01,Equations!$D$6+Equations!$D$7*G10+Equations!$D$8*I10+Equations!$D$10*G10^2+Equations!$D$11*G10*I10+Equations!$D$13*I10^2) -> 0.64516425 | Q10: =P10-O10 -> 0.000164248
A11: 7 | B11: Rosti et al. | C11: Compatible-Empirical | D11: 2 | E11: 6 | F11: 4.9 | G11: 0.368 | H11: 1.225 | I11: 3.5 | J11: 0.422 | K11: 0.468 | L11: =MAX(0.01,Equations!$C$6+Equations!$C$7*G11+Equations!$C$8*I11+Equations!$C$9*H11+Equations!$C$10*G11^2+Equations!$C$11*G11*I11+Equations!$C$12*G11*H11+Equations!$C$13*I11^2+Equations!$C$14*I11*H11+Equations!$C$15*H11^2) -> 0.46708928 | M11: =L11-K11 -> -0.0009107161 | N11: 1.163 | O11: 0.975 | P11: =MAX(0.01,Equations!$D$6+Equations!$D$7*G11+Equations!$D$8*I11+Equations!$D$10*G11^2+Equations!$D$11*G11*I11+Equations!$D$13*I11^2) -> 0.97388539 | Q11: =P11-O11 -> -0.001114608
A12: 8 | B12: Rosti et al. | C12: Compatible-Empirical | D12: 4 | E12: 12 | F12: 4.9 | G12: 0.437 | H12: 1.299 | I12: 3.5 | J12: 0.253 | K12: 0.406 | L12: =MAX(0.01,Equations!$C$6+Equations!$C$7*G12+Equations!$C$8*I12+Equations!$C$9*H12+Equations!$C$10*G12^2+Equations!$C$11*G12*I12+Equations!$C$12*G12*H12+Equations!$C$13*I12^2+Equations!$C$14*I12*H12+Equations!$C$15*H12^2) -> 0.40571056 | M12: =L12-K12 -> -0.0002894439 | N12: 0.774 | O12: 0.871 | P12: =MAX(0.01,Equations!$D$6+Equations!$D$7*G12+Equations!$D$8*I12+Equations!$D$10*G12^2+Equations!$D$11*G12*I12+Equations!$D$13*I12^2) -> 0.87095309 | Q12: =P12-O12 -> -4.69105e-05
A13: 9 | B13: Rosti et al. | C13: Compatible-Empirical | D13: 6 | E13: 18 | F13: 8.5 | G13: 0.484 | H13: 1.767 | I13: 3.5 | J13: 0.183 | K13: 0.318 | L13: =MAX(0.01,Equations!$C$6+Equations!$C$7*G13+Equations!$C$8*I13+Equations!$C$9*H13+Equations!$C$10*G13^2+Equations!$C$11*G13*I13+Equations!$C$12*G13*H13+Equations!$C$13*I13^2+Equations!$C$14*I13*H13+Equations!$C$15*H13^2) -> 0.31759079 | M13: =L13-K13 -> -0.0004092121 | N13: 0.351 | O13: 0.807 | P13: =MAX(0.01,Equations!$D$6+Equations!$D$7*G13+Equations!$D$8*I13+Equations!$D$10*G13^2+Equations!$D$11*G13*I13+Equations!$D$13*I13^2) -> 0.80626725 | Q13: =P13-O13 -> -0.000732752
A14: 10 | B14: Biglari et al. | C14: Incompatible-Typology* | D14: 2 | E14: 6 | F14: 4.9 | G14: 0.368 | H14: 1.225 | I14: 2 | J14: 0.1 | K14: 0.347 | L14: =MAX(0.01,Equations!$C$6+Equations!$C$7*G14+Equations!$C$8*I14+Equations!$C$9*H14+Equations!$C$10*G14^2+Equations!$C$11*G14*I14+Equations!$C$12*G14*H14+Equations!$C$13*I14^2+Equations!$C$14*I14*H14+Equations!$C$15*H14^2) -> 0.34689218 | M14: =L14-K14 -> -0.0001078161 | N14: 0.23 | O14: 0.799 | P14: =MAX(0.01,Equations!$D$6+Equations!$D$7*G14+Equations!$D$8*I14+Equations!$D$10*G14^2+Equations!$D$11*G14*I14+Equations!$D$13*I14^2) -> 0.79807939 | Q14: =P14-O14 -> -0.000920608
A15: 11 | B15: Biglari et al. | C15: Incompatible-Typology* | D15: 5 | E15: 15 | F15: 7.7 | G15: 0.462 | H15: 1.549 | I15: 2.6 | J15: 0.18 | K15: 0.303 | L15: =MAX(0.01,Equations!$C$6+Equations!$C$7*G15+Equations!$C$8*I15+Equations!$C$9*H15+Equations!$C$10*G15^2+Equations!$C$11*G15*I15+Equations!$C$12*G15*H15+Equations!$C$13*I15^2+Equations!$C$14*I15*H15+Equations!$C$15*H15^2) -> 0.30281911 | M15: =L15-K15 -> -0.0001808889 | N15: 0.35 | O15: 0.739 | P15: =MAX(0.01,Equations!$D$6+Equations!$D$7*G15+Equations!$D$8*I15+Equations!$D$10*G15^2+Equations!$D$11*G15*I15+Equations!$D$13*I15^2) -> 0.7392833 | Q15: =P15-O15 -> 0.000283302
A16: 12 | B16: Biglari et al. | C16: Incompatible-Typology* | D16: 4 | E16: 12 | F16: 6.9 | G16: 0.437 | H16: 1.732 | I16: 2.3 | J16: 0.11 | K16: 0.282 | L16: =MAX(0.01,Equations!$C$6+Equations!$C$7*G16+Equations!$C$8*I16+Equations!$C$9*H16+Equations!$C$10*G16^2+Equations!$C$11*G16*I16+Equations!$C$12*G16*H16+Equations!$C$13*I16^2+Equations!$C$14*I16*H16+Equations!$C$15*H16^2) -> 0.28226151 | M16: =L16-K16 -> 0.0002615102 | N16: 0.25 | O16: 0.738 | P16: =MAX(0.01,Equations!$D$6+Equations!$D$7*G16+Equations!$D$8*I16+Equations!$D$10*G16^2+Equations!$D$11*G16*I16+Equations!$D$13*I16^2) -> 0.73838489 | Q16: =P16-O16 -> 0.0003848895
A17: 13 | B17: Del Gaudio et al. | C17: Compatible-Empirical | D17: 2 | E17: 6.5 | F17: 5.1 | G17: 0.375 | H17: 1.275 | I17: 1 | J17: 0.2 | K17: 0.252 | L17: =MAX(0.01,Equations!$C$6+Equations!$C$7*G17+Equations!$C$8*I17+Equations!$C$9*H17+Equations!$C$10*G17^2+Equations!$C$11*G17*I17+Equations!$C$12*G17*H17+Equations!$C$13*I17^2+Equations!$C$14*I17*H17+Equations!$C$15*H17^2) -> 0.25238356 | M17: =L17-K17 -> 0.0003835625 | N17: 1.23 | O17: 0.664 | P17: =MAX(0.01,Equations!$D$6+Equations!$D$7*G17+Equations!$D$8*I17+Equations!$D$10*G17^2+Equations!$D$11*G17*I17+Equations!$D$13*I17^2) -> 0.66397969 | Q17: =P17-O17 -> -2.03125e-05
A18: 14 | B18: Del Gaudio et al. | C18: Compatible-Empirical | D18: 5 | E18: 16.5 | F18: 8.1 | G18: 0.473 | H18: 2.031 | I18: 1 | J18: 0.14 | K18: 0.161 | L18: =MAX(0.01,Equations!$C$6+Equations!$C$7*G18+Equations!$C$8*I18+Equations!$C$9*H18+Equations!$C$10*G18^2+Equations!$C$11*G18*I18+Equations!$C$12*G18*H18+Equations!$C$13*I18^2+Equations!$C$14*I18*H18+Equations!$C$15*H18^2) -> 0.16181412 | M18: =L18-K18 -> 0.0008141241 | N18: 0.38 | O18: 0.542 | P18: =MAX(0.01,Equations!$D$6+Equations!$D$7*G18+Equations!$D$8*I18+Equations!$D$10*G18^2+Equations!$D$11*G18*I18+Equations!$D$13*I18^2) -> 0.54268352 | Q18: =P18-O18 -> 0.0006835195
A19: 15 | B19: Altunışık et al. | C19: Compatible-Empirical | D19: 2 | E19: 6 | F19: 4.9 | G19: 0.368 | H19: 1.225 | I19: 0.8 | J19: 0.18 | K19: 0.241 | L19: =MAX(0.01,Equations!$C$6+Equations!$C$7*G19+Equations!$C$8*I19+Equations!$C$9*H19+Equations!$C$10*G19^2+Equations!$C$11*G19*I19+Equations!$C$12*G19*H19+Equations!$C$13*I19^2+Equations!$C$14*I19*H19+Equations!$C$15*H19^2) -> 0.2410145 | M19: =L19-K19 -> 1.45039e-05 | N19: 0.87 | O19: 0.648 | P19: =MAX(0.01,Equations!$D$6+Equations!$D$7*G19+Equations!$D$8*I19+Equations!$D$10*G19^2+Equations!$D$11*G19*I19+Equations!$D$13*I19^2) -> 0.64771459 | Q19: =P19-O19 -> -0.000285408
... A25: 21 | B25: Altunışık et al. | C25: Compatible-Empirical | D25: 5 | E25: 15 | F25: 7.7 | G25: 0.462 | H25: 1.936 | I25: 1.3 | J25: 0.1 | K25: 0.19 | L25: =MAX(0.01,Equations!$C$6+Equations!$C$7*G25+Equations!$C$8*I25+Equations!$C$9*H25+Equations!$C$10*G25^2+Equations!$C$11*G25*I25+Equations!$C$12*G25*H25+Equations!$C$13*I25^2+Equations!$C$14*I25*H25+Equations!$C$15*H25^2) -> 0.1906459 | M25: =L25-K25 -> 0.0006459016 | N25: 0.39 | O25: 0.591 | P25: =MAX(0.01,Equations!$D$6+Equations!$D$7*G25+Equations!$D$8*I25+Equations!$D$10*G25^2+Equations!$D$11*G25*I25+Equations!$D$13*I25^2) -> 0.591004 | Q25: =P25-O25 -> 4.002e-06
A26: 22 | B26: Altunışık et al. | C26: Compatible-Empirical | D26: 9 | E26: 27 | F26: 10.4 | G26: 0.535 | H26: 2.589 | I26: 1.2 | J26: 0.1 | K26: 0.121 | L26: =MAX(0.01,Equations!$C$6+Equations!$C$7*G26+Equations!$C$8*I26+Equations!$C$9*H26+Equations!$C$10*G26^2+Equations!$C$11*G26*I26+Equations!$C$12*G26*H26+Equations!$C$13*I26^2+Equations!$C$14*I26*H26+Equations!$C$15*H26^2) -> 0.11789887 | M26: =L26-K26 -> -0.0031011263 | N26: 0.41 | O26: 0.509 | P26: =MAX(0.01,Equations!$D$6+Equations!$D$7*G26+Equations!$D$8*I26+Equations!$D$10*G26^2+Equations!$D$11*G26*I26+Equations!$D$13*I26^2) -> 0.49841899 | Q26: =P26-O26 -> -0.010581013 | R26: Small mismatch: A.16 λeff 2.589 vs 2.598 in neighbouring rows.
A27: 23 | B27: Altunışık et al. | C27: Compatible-Empirical | D27: 2 | E27: 6 | F27: 4.9 | G27: 0.368 | H27: 1.225 | I27: 1.8 | J27: 0.33 | K27: 0.33 | L27: =MAX(0.01,Equations!$C$6+Equations!$C$7*G27+Equations!$C$8*I27+Equations!$C$9*H27+Equations!$C$10*G27^2+Equations!$C$11*G27*I27+Equations!$C$12*G27*H27+Equations!$C$13*I27^2+Equations!$C$14*I27*H27+Equations!$C$15*H27^2) -> 0.3298459 | M27: =L27-K27 -> -0.0001540961 | N27: 2.42 | O27: 0.774 | P27: =MAX(0.01,Equations!$D$6+Equations!$D$7*G27+Equations!$D$8*I27+Equations!$D$10*G27^2+Equations!$D$11*G27*I27+Equations!$D$13*I27^2) -> 0.77361859 | Q27: =P27-O27 -> -0.000381408
A28: 24 | B28: Altunışık et al. | C28: Compatible-Empirical | D28: 5 | E28: 15 | F28: 7.7 | G28: 0.462 | H28: 1.936 | I28: 1.8 | J28: 0.11 | K28: 0.221 | L28: =MAX(0.01,Equations!$C$6+Equations!$C$7*G28+Equations!$C$8*I28+Equations!$C$9*H28+Equations!$C$10*G28^2+Equations!$C$11*G28*I28+Equations!$C$12*G28*H28+Equations!$C$13*I28^2+Equations!$C$14*I28*H28+Equations!$C$15*H28^2) -> 0.2210919 | M28: =L28-K28 -> 9.19016e-05 | N28: 0.5 | O28: 0.649 | P28: =MAX(0.01,Equations!$D$6+Equations!$D$7*G28+Equations!$D$8*I28+Equations!$D$10*G28^2+Equations!$D$11*G28*I28+Equations!$D$13*I28^2) -> 0.6492345 | Q28: =P28-O28 -> 0.000234502
A29: 25 | B29: Altunışık et al. | C29: Compatible-Empirical | D29: 9 | E29: 27 | F29: 10.4 | G29: 0.535 | H29: 2.598 | I29: 1.8 | J29: 0.05 | K29: 0.14 | L29: =MAX(0.01,Equations!$C$6+Equations!$C$7*G29+Equations!$C$8*I29+Equations!$C$9*H29+Equations!$C$10*G29^2+Equations!$C$11*G29*I29+Equations!$C$12*G29*H29+Equations!$C$13*I29^2+Equations!$C$14*I29*H29+Equations!$C$15*H29^2) -> 0.14023191 | M29: =L29-K29 -> 0.0002319138 | N29: 0.4 | O29: 0.564 | P29: =MAX(0.01,Equations!$D$6+Equations!$D$7*G29+Equations!$D$8*I29+Equations!$D$10*G29^2+Equations!$D$11*G29*I29+Equations!$D$13*I29^2) -> 0.56477449 | Q29: =P29-O29 -> 0.0007744875
A30: 26 | B30: Altunışık et al. | C30: Compatible-Empirical | D30: 2 | E30: 6 | F30: 4.9 | G30: 0.368 | H30: 1.225 | I30: 2.5 | J30: 0.65 | K30: 0.389 | L30: =MAX(0.01,Equations!$C$6+Equations!$C$7*G30+Equations!$C$8*I30+Equations!$C$9*H30+Equations!$C$10*G30^2+Equations!$C$11*G30*I30+Equations!$C$12*G30*H30+Equations!$C$13*I30^2+Equations!$C$14*I30*H30+Equations!$C$15*H30^2) -> 0.38845788 | M30: =L30-K30 -> -0.0005421161 | N30: — | O30: 0.859 | P30: =MAX(0.01,Equations!$D$6+Equations!$D$7*G30+Equations!$D$8*I30+Equations!$D$10*G30^2+Equations!$D$11*G30*I30+Equations!$D$13*I30^2) -> 0.85818139 | Q30: =P30-O30 -> -0.000818608
A31: 27 | B31: Altunışık et al. | C31: Compatible-Empirical | D31: 5 | E31: 15 | F31: 7.7 | G31: 0.462 | H31: 1.936 | I31: 2.5 | J31: 0.14 | K31: 0.261 | L31: =MAX(0.01,Equations!$C$6+Equations!$C$7*G31+Equations!$C$8*I31+Equations!$C$9*H31+Equations!$C$10*G31^2+Equations!$C$11*G31*I31+Equations!$C$12*G31*H31+Equations!$C$13*I31^2+Equations!$C$14*I31*H31+Equations!$C$15*H31^2) -> 0.2611963 | M31: =L31-K31 -> 0.0001963016 | N31: 0.86 | O31: 0.728 | P31: =MAX(0.01,Equations!$D$6+Equations!$D$7*G31+Equations!$D$8*I31+Equations!$D$10*G31^2+Equations!$D$11*G31*I31+Equations!$D$13*I31^2) -> 0.7282372 | Q31: =P31-O31 -> 0.000237202
A32: 28 | B32: Altunışık et al. | C32: Compatible-Empirical | D32: 9 | E32: 27 | F32: 10.4 | G32: 0.535 | H32: 2.598 | I32: 2.5 | J32: 0.1 | K32: 0.164 | L32: =MAX(0.01,Equations!$C$6+Equations!$C$7*G32+Equations!$C$8*I32+Equations!$C$9*H32+Equations!$C$10*G32^2+Equations!$C$11*G32*I32+Equations!$C$12*G32*H32+Equations!$C$13*I32^2+Equations!$C$14*I32*H32+Equations!$C$15*H32^2) -> 0.16407195 | M32: =L32-K32 -> 7.19538e-05 | N32: 0.62 | O32: 0.639 | P32: =MAX(0.01,Equations!$D$6+Equations!$D$7*G32+Equations!$D$8*I32+Equations!$D$10*G32^2+Equations!$D$11*G32*I32+Equations!$D$13*I32^2) -> 0.63945924 | Q32: =P32-O32 -> 0.0004592375
A33: 29 | B33: Altunışık et al. | C33: Compatible-Empirical | D33: 2 | E33: 6 | F33: 4.9 | G33: 0.368 | H33: 1.225 | I33: 3 | J33: 1.41 | K33: 0.429 | L33: =MAX(0.01,Equations!$C$6+Equations!$C$7*G33+Equations!$C$8*I33+Equations!$C$9*H33+Equations!$C$10*G33^2+Equations!$C$11*G33*I33+Equations!$C$12*G33*H33+Equations!$C$13*I33^2+Equations!$C$14*I33*H33+Equations!$C$15*H33^2) -> 0.42852358 | M33: =L33-K33 -> -0.0004764161 | N33: — | O33: 0.918 | P33: =MAX(0.01,Equations!$D$6+Equations!$D$7*G33+Equations!$D$8*I33+Equations!$D$10*G33^2+Equations!$D$11*G33*I33+Equations!$D$13*I33^2) -> 0.91678339 | Q33: =P33-O33 -> -0.001216608
A34: 30 | B34: Altunışık et al. | C34: Compatible-Empirical | D34: 5 | E34: 15 | F34: 7.7 | G34: 0.462 | H34: 1.936 | I34: 3 | J34: 0.2 | K34: 0.288 | L34: =MAX(0.01,Equations!$C$6+Equations!$C$7*G34+Equations!$C$8*I34+Equations!$C$9*H34+Equations!$C$10*G34^2+Equations!$C$11*G34*I34+Equations!$C$12*G34*H34+Equations!$C$13*I34^2+Equations!$C$14*I34*H34+Equations!$C$15*H34^2) -> 0.2880423 | M34: =L34-K34 -> 4.23016e-05 | N34: 1.34 | O34: 0.783 | P34: =MAX(0.01,Equations!$D$6+Equations!$D$7*G34+Equations!$D$8*I34+Equations!$D$10*G34^2+Equations!$D$11*G34*I34+Equations!$D$13*I34^2) -> 0.7828677 | Q34: =P34-O34 -> -0.000132298
A35: 31 | B35: Altunışık et al. | C35: Compatible-Empirical | D35: 9 | E35: 27 | F35: 10.4 | G35: 0.535 | H35: 2.598 | I35: 2.5 | J35: 0.12 | K35: 0.179 | L35: =MAX(0.01,Equations!$C$6+Equations!$C$7*G35+Equations!$C$8*I35+Equations!$C$9*H35+Equations!$C$10*G35^2+Equations!$C$11*G35*I35+Equations!$C$12*G35*H35+Equations!$C$13*I35^2+Equations!$C$14*I35*H35+Equations!$C$15*H35^2) -> 0.16407195 | M35: =L35-K35 -> -0.014928046 | N35: 0.71 | O35: 0.691 | P35: =MAX(0.01,Equations!$D$6+Equations!$D$7*G35+Equations!$D$8*I35+Equations!$D$10*G35^2+Equations!$D$11*G35*I35+Equations!$D$13*I35^2) -> 0.63945924 | Q35: =P35-O35 -> -0.051540763 | R35: A.17 prediction matches SR = 3.0; A.16 lists 2.5.
A36: 32 | B36: Tsoumani et al. | C36: Incompatible-Typology* | D36: 2 | E36: 8 | F36: 5.7 | G36: 0.395 | H36: 1.414 | I36: 3 | J36: 0.15 | K36: 0.233 | L36: =MAX(0.01,Equations!$C$6+Equations!$C$7*G36+Equations!$C$8*I36+Equations!$C$9*H36+Equations!$C$10*G36^2+Equations!$C$11*G36*I36+Equations!$C$12*G36*H36+Equations!$C$13*I36^2+Equations!$C$14*I36*H36+Equations!$C$15*H36^2) -> 0.38823486 | M36: =L36-K36 -> 0.15523486 | N36: 0.36 | O36: 0.638 | P36: =MAX(0.01,Equations!$D$6+Equations!$D$7*G36+Equations!$D$8*I36+Equations!$D$10*G36^2+Equations!$D$11*G36*I36+Equations!$D$13*I36^2) -> 0.87651739 | Q36: =P36-O36 -> 0.23851739 | R36: A.16 inputs do not reproduce the A.17 prediction.
A37: 33 | B37: Panda et al. | C37: Compatible-Analytical | D37: 2 | E37: 6 | F37: 4.9 | G37: 0.368 | H37: 1.225 | I37: 4.43 | J37: 0.75 | K37: 0.536 | L37: =MAX(0.01,Equations!$C$6+Equations!$C$7*G37+Equations!$C$8*I37+Equations!$C$9*H37+Equations!$C$10*G37^2+Equations!$C$11*G37*I37+Equations!$C$12*G37*H37+Equations!$C$13*I37^2+Equations!$C$14*I37*H37+Equations!$C$15*H37^2) -> 0.53483179 | M37: =L37-K37 -> -0.0011682141 | N37: 1.25 | O37: 1.077 | P37: =MAX(0.01,Equations!$D$6+Equations!$D$7*G37+Equations!$D$8*I37+Equations!$D$10*G37^2+Equations!$D$11*G37*I37+Equations!$D$13*I37^2) -> 1.0761054 | Q37: =P37-O37 -> -0.000894588
A38: 34 | B38: Panda et al. | C38: Compatible-Analytical | D38: 4 | E38: 12 | F38: 4.9 | G38: 0.437 | H38: 1.732 | I38: 3.25 | J38: 0.7 | K38: 0.341 | L38: =MAX(0.01,Equations!$C$6+Equations!$C$7*G38+Equations!$C$8*I38+Equations!$C$9*H38+Equations!$C$10*G38^2+Equations!$C$11*G38*I38+Equations!$C$12*G38*H38+Equations!$C$13*I38^2+Equations!$C$14*I38*H38+Equations!$C$15*H38^2) -> 0.34015489 | M38: =L38-K38 -> -0.0008451098 | N38: 1.2 | O38: 0.844 | P38: =MAX(0.01,Equations!$D$6+Equations!$D$7*G38+Equations!$D$8*I38+Equations!$D$10*G38^2+Equations!$D$11*G38*I38+Equations!$D$13*I38^2) -> 0.84404721 | Q38: =P38-O38 -> 4.72145e-05
A39: 35 | B39: Panda et al. | C39: Compatible-Analytical | D39: 8 | E39: 24 | F39: 9.8 | G39: 0.52 | H39: 2.449 | I39: 6.75 | J39: 0.4 | K39: 0.29 | L39: =MAX(0.01,Equations!$C$6+Equations!$C$7*G39+Equations!$C$8*I39+Equations!$C$9*H39+Equations!$C$10*G39^2+Equations!$C$11*G39*I39+Equations!$C$12*G39*H39+Equations!$C$13*I39^2+Equations!$C$14*I39*H39+Equations!$C$15*H39^2) -> 0.28748249 | M39: =L39-K39 -> -0.0025175053 | N39: 0.7 | O39: 1.054 | P39: =MAX(0.01,Equations!$D$6+Equations!$D$7*G39+Equations!$D$8*I39+Equations!$D$10*G39^2+Equations!$D$11*G39*I39+Equations!$D$13*I39^2) -> 1.0525527 | Q39: =P39-O39 -> -0.0014473
A40: 36 | B40: Panda et al. | C40: Compatible-Analytical | D40: 12 | E40: 36 | F40: 12 | G40: 0.575 | H40: 3 | I40: 12.93 | J40: 0.25 | K40: 0.01 | L40: =MAX(0.01,Equations!$C$6+Equations!$C$7*G40+Equations!$C$8*I40+Equations!$C$9*H40+Equations!$C$10*G40^2+Equations!$C$11*G40*I40+Equations!$C$12*G40*H40+Equations!$C$13*I40^2+Equations!$C$14*I40*H40+Equations!$C$15*H40^2) -> 0.01 | M40: =L40-K40 -> 0 | N40: 0.4 | O40: 1.328 | P40: =MAX(0.01,Equations!$D$6+Equations!$D$7*G40+Equations!$D$8*I40+Equations!$D$10*G40^2+Equations!$D$11*G40*I40+Equations!$D$13*I40^2) -> 1.3246051 | Q40: =P40-O40 -> -0.0033948875
A41: 37 | B41: Abbasi et al. | C41: Nonstandard-Precondition* | D41: 2 | E41: 4.3 | F41: 4.1 | G41: 0.338 | H41: 1.037 | I41: 1 | J41: 0.336 | K41: 0.288 | L41: =MAX(0.01,Equations!$C$6+Equations!$C$7*G41+Equations!$C$8*I41+Equations!$C$9*H41+Equations!$C$10*G41^2+Equations!$C$11*G41*I41+Equations!$C$12*G41*H41+Equations!$C$13*I41^2+Equations!$C$14*I41*H41+Equations!$C$15*H41^2) -> 0.28797849 | M41: =L41-K41 -> -2.15113e-05 | N41: 0.29 | O41: 0.714 | P41: =MAX(0.01,Equations!$D$6+Equations!$D$7*G41+Equations!$D$8*I41+Equations!$D$10*G41^2+Equations!$D$11*G41*I41+Equations!$D$13*I41^2) -> 0.7147477 | Q41: =P41-O41 -> 0.000747702
A42: 38 | B42: Abbasi et al. | C42: Nonstandard-Precondition* | D42: 2 | E42: 4.3 | F42: 4.1 | G42: 0.338 | H42: 1.037 | I42: 1 | J42: 0.279 | K42: 0.288 | L42: =MAX(0.01,Equations!$C$6+Equations!$C$7*G42+Equations!$C$8*I42+Equations!$C$9*H42+Equations!$C$10*G42^2+Equations!$C$11*G42*I42+Equations!$C$12*G42*H42+Equations!$C$13*I42^2+Equations!$C$14*I42*H42+Equations!$C$15*H42^2) -> 0.28797849 | M42: =L42-K42 -> -2.15113e-05 | N42: 0.66 | O42: 0.714 | P42: =MAX(0.01,Equations!$D$6+Equations!$D$7*G42+Equations!$D$8*I42+Equations!$D$10*G42^2+Equations!$D$11*G42*I42+Equations!$D$13*I42^2) -> 0.7147477 | Q42: =P42-O42 -> 0.000747702
